<sdf version="1.7">
  <world name="world">
    <scene>
      <ambient>0.8 0.8 0.8 1.0</ambient>
      <background>0 0 0</background>
      <grid>false</grid>
    </scene>
    <include>
      <uri>model://sun</uri>
    </include>
    <gui>
      <camera name="gui_camera">
        <pose>5.020931721545171 -31.664112905432397 10 0 0.6 1.57</pose>
      </camera>
      <plugin name="toggle_charging" filename="libtoggle_charging.so" />
      <plugin name="toggle_floors" filename="libtoggle_floors.so">
        <floor name="cafe_floor0" model_name="cafe_rmf_cafe_floor0">
          <model name="OpenRobotics/Cafe table" />
          <model name="OpenRobotics/Cafe table_2" />
          <model name="OpenRobotics/Cafe table_3" />
          <model name="OpenRobotics/Cafe table_4" />
          <model name="OpenRobotics/Cafe table_5" />
          <model name="null" />
        </floor>
      </plugin>
    </gui>
    <include>
      <name>OpenRobotics/Cafe table</name>
      <uri>model://Cafe table</uri>
      <pose>5.921023109715055 -13.062652883652463 0.0 0 0 1.5708</pose>
      <static>True</static>
    </include>
    <include>
      <name>OpenRobotics/Cafe table_2</name>
      <uri>model://Cafe table</uri>
      <pose>8.076032768404867 -17.441952095087476 0.0 0 0 1.5708</pose>
      <static>True</static>
    </include>
    <include>
      <name>OpenRobotics/Cafe table_3</name>
      <uri>model://Cafe table</uri>
      <pose>3.878196533816359 -17.50482934490552 0.0 0 0 1.5708</pose>
      <static>True</static>
    </include>
    <include>
      <name>OpenRobotics/Cafe table_4</name>
      <uri>model://Cafe table</uri>
      <pose>3.860192517114761 -21.576801632947898 0.0 0 0 1.5708</pose>
      <static>True</static>
    </include>
    <include>
      <name>OpenRobotics/Cafe table_5</name>
      <uri>model://Cafe table</uri>
      <pose>8.03105008837838 -21.585831003026207 0.0 0 0 1.5708</pose>
      <static>True</static>
    </include>
    <model name="null">
      <pose>1.5708367763507116 -23.308853707787698 0.0 0 0 3.141592653589793</pose>
      <link name="right">
        <pose>0 0 1.11 0 0 0</pose>
        <visual name="right_visual">
          <geometry>
            <box>
              <size>1.151778950075792 0.03 2.2</size>
            </box>
          </geometry>
          <material>
            <ambient>0.5 0.25 0 0.6</ambient>
            <diffuse>0.5 0.25 0 0.6</diffuse>
          </material>
        </visual>
        <collision name="right_collision">
          <geometry>
            <box>
              <size>1.151778950075792 0.03 2.2</size>
            </box>
          </geometry>
          <surface>
            <contact>
              <collide_bitmask>0x02</collide_bitmask>
            </contact>
          </surface>
        </collision>
        <inertial>
          <mass>50.0</mass>
          <inertia>
            <ixx>20.17041666666667</ixx>
            <iyy>25.694144790990393</iyy>
            <izz>5.531228124323724</izz>
          </inertia>
        </inertial>
      </link>
      <joint name="right_joint" type="revolute">
        <parent>world</parent>
        <child>right</child>
        <axis>
          <xyz>0 0 -1</xyz>
          <limit>
            <lower>0</lower>
            <upper>1.57</upper>
          </limit>
        </axis>
        <pose>0.580889475037896 0 0 0 0 0</pose>
      </joint>
      <plugin name="door" filename="libdoor.so">
        <v_max_door>0.5</v_max_door>
        <a_max_door>0.3</a_max_door>
        <a_nom_door>0.15</a_nom_door>
        <dx_min_door>0.01</dx_min_door>
        <f_max_door>500.0</f_max_door>
        <door name="null" type="SwingDoor" left_joint_name="empty_joint" right_joint_name="right_joint" />
      </plugin>
    </model>
    <include>
      <name>cafe_rmf_cafe_floor0</name>
      <uri>model://cafe_rmf_cafe_floor0</uri>
      <pose>0 0 0.0 0 0 0</pose>
    </include>
    <rmf_charger_waypoints name="charger_waypoints">
      <rmf_vertex name="d_bot_charging_station" x="8.919923168269152" y="-0.9850221903610107" level="cafe_floor0" />
    </rmf_charger_waypoints>
  </world>
</sdf>
